Workbook

Sheet AB Test Analysis
A1: Milestone | A/B Testing for H&M | F1: group | G1: subject line | H1: opened
F2: control | G2: =IF(ABTest[[#This Row],[group]]="control","20% off + free shipping","Your last chance to score 20% off + free shipping") -> 20% off + free shipping | H2: 0
A3: • All of your answers should be typed or pasted into the grey boxes. • Questions with grey answer boxes expect a specific answer. Once you input the correct answer, the question number box will change from blue to green. • Questions with yellow answer boxes are free-response questions. There will be no change in the question number boxes (in blue), regardless of your answer. • Hover your cursor over the blue hint box to get a helpful hint! | F3: control | G3: =IF(ABTest[[#This Row],[group]]="control","20% off + free shipping","Your last chance to score 20% off + free shipping") -> 20% off + free shipping | H3: 0
F4: control | G4: =IF(ABTest[[#This Row],[group]]="control","20% off + free shipping","Your last chance to score 20% off + free shipping") -> 20% off + free shipping | H4: 0
F5: test | G5: =IF(ABTest[[#This Row],[group]]="control","20% off + free shipping","Your last chance to score 20% off + free shipping") -> Your last chance to score 20% off + free shipping | H5: 0
F6: test | G6: =IF(ABTest[[#This Row],[group]]="control","20% off + free shipping","Your last chance to score 20% off + free shipping") -> Your last chance to score 20% off + free shipping | H6: 0
F7: test | G7: =IF(ABTest[[#This Row],[group]]="control","20% off + free shipping","Your last chance to score 20% off + free shipping") -> Your last chance to score 20% off + free shipping | H7: 0
F8: control | G8: =IF(ABTest[[#This Row],[group]]="control","20% off + free shipping","Your last chance to score 20% off + free shipping") -> 20% off + free shipping | H8: 0
F9: control | G9: =IF(ABTest[[#This Row],[group]]="control","20% off + free shipping","Your last chance to score 20% off + free shipping") -> 20% off + free shipping | H9: 0
F10: test | G10: =IF(ABTest[[#This Row],[group]]="control","20% off + free shipping","Your last chance to score 20% off + free shipping") -> Your last chance to score 20% off + free shipping | H10: 1
F11: test | G11: =IF(ABTest[[#This Row],[group]]="control","20% off + free shipping","Your last chance to score 20% off + free shipping") -> Your last chance to score 20% off + free shipping | H11: 0
F12: test | G12: =IF(ABTest[[#This Row],[group]]="control","20% off + free shipping","Your last chance to score 20% off + free shipping") -> Your last chance to score 20% off + free shipping | H12: 0
F13: test | G13: =IF(ABTest[[#This Row],[group]]="control","20% off + free shipping","Your last chance to score 20% off + free shipping") -> Your last chance to score 20% off + free shipping | H13: 0
A14: Part 1: A/B Test Design & Identifying Potential Issues | F14: control | G14: =IF(ABTest[[#This Row],[group]]="control","20% off + free shipping","Your last chance to score 20% off + free shipping") -> 20% off + free shipping | H14: 0
F15: control | G15: =IF(ABTest[[#This Row],[group]]="control","20% off + free shipping","Your last chance to score 20% off + free shipping") -> 20% off + free shipping | H15: 1
A16: 1 | B16: In a sentence or two, state the null hypothesis for H&M's A/B test. | F16: test | G16: =IF(ABTest[[#This Row],[group]]="control","20% off + free shipping","Your last chance to score 20% off + free shipping") -> Your last chance to score 20% off + free shipping | H16: 0
A17: The subject line has no effect on the email open rate. The open rate for the test group is equal to the open rate for the control group. | F17: control | G17: =IF(ABTest[[#This Row],[group]]="control","20% off + free shipping","Your last chance to score 20% off + free shipping") -> 20% off + free shipping | H17: 0
F18: control | G18: =IF(ABTest[[#This Row],[group]]="control","20% off + free shipping","Your last chance to score 20% off + free shipping") -> 20% off + free shipping | H18: 0
A19: 2 | B19: In a sentence or two, state the alternative hypothesis for H&M's A/B test. | F19: test | G19: =IF(ABTest[[#This Row],[group]]="control","20% off + free shipping","Your last chance to score 20% off + free shipping") -> Your last chance to score 20% off + free shipping | H19: 0
A20: The urgency-based subject line produces a higher open rate than the control subject line. | F20: test | G20: =IF(ABTest[[#This Row],[group]]="control","20% off + free shipping","Your last chance to score 20% off + free shipping") -> Your last chance to score 20% off + free shipping | H20: 0
F21: control | G21: =IF(ABTest[[#This Row],[group]]="control","20% off + free shipping","Your last chance to score 20% off + free shipping") -> 20% off + free shipping | H21: 0
A22: Use the A/B Test Sample Size Calculator linked below to help you answer the following questions. | F22: test | G22: =IF(ABTest[[#This Row],[group]]="control","20% off + free shipping","Your last chance to score 20% off + free shipping") -> Your last chance to score 20% off + free shipping | H22: 0
A23: =HYPERLINK("https://www.statsig.com/calculator","A/B Test Sample Size Calculator") -> A/B Test Sample Size Calculator | F23: control | G23: =IF(ABTest[[#This Row],[group]]="control","20% off + free shipping","Your last chance to score 20% off + free shipping") -> 20% off + free shipping | H23: 0
A24: Historically, promotional emails have had an open rate of 18%. The company wants to see the new subject line increase that to an open rate of 20%. | F24: control | G24: =IF(ABTest[[#This Row],[group]]="control","20% off + free shipping","Your last chance to score 20% off + free shipping") -> 20% off + free shipping | H24: 0
F25: test | G25: =IF(ABTest[[#This Row],[group]]="control","20% off + free shipping","Your last chance to score 20% off + free shipping") -> Your last chance to score 20% off + free shipping | H25: 1
A26: 3 | B26: What is the minimum detectable effect associated with that increase in open rate? | C26: 0.1111 | D26: Hint! | F26: control | G26: =IF(ABTest[[#This Row],[group]]="control","20% off + free shipping","Your last chance to score 20% off + free shipping") -> 20% off + free shipping | H26: 0
F27: control | G27: =IF(ABTest[[#This Row],[group]]="control","20% off + free shipping","Your last chance to score 20% off + free shipping") -> 20% off + free shipping | H27: 0
A28: 4 | B28: What total sample size is required to reliably detect that level of increase? | C28: 9400 | D28: Hint! | F28: test | G28: =IF(ABTest[[#This Row],[group]]="control","20% off + free shipping","Your last chance to score 20% off + free shipping") -> Your last chance to score 20% off + free shipping | H28: 0
F29: test | G29: =IF(ABTest[[#This Row],[group]]="control","20% off + free shipping","Your last chance to score 20% off + free shipping") -> Your last chance to score 20% off + free shipping | H29: 1
A30: Before launching any A/B test, it’s crucial to identify potential risks or confounding factors that could skew the results. As the analyst, you need to be prepared to be asked "How do we know if this test is valid?" | F30: test | G30: =IF(ABTest[[#This Row],[group]]="control","20% off + free shipping","Your last chance to score 20% off + free shipping") -> Your last chance to score 20% off + free shipping | H30: 0
F31: control | G31: =IF(ABTest[[#This Row],[group]]="control","20% off + free shipping","Your last chance to score 20% off + free shipping") -> 20% off + free shipping | H31: 0
A32: 5 | B32: Use ChatGPT to generate a list of confounding factors by asking "What factors could skew the results of an A/B test like this, and how might they influence our findings or effect the results?" You might also try "What are common mistakes to avoid when designing an A/B test?" After reviewing ChatGPT’s response, identify at least two confounding factors that could impact the experiment. Write a develop a brief strategy (one-to-two sentences) for how you would mitigate these issues if you were a part of designing a similar A/B test. | F32: control | G32: =IF(ABTest[[#This Row],[group]]="control","20% off + free shipping","Your last chance to score 20% off + free shipping") -> 20% off + free shipping | H32: 0
F33: control | G33: =IF(ABTest[[#This Row],[group]]="control","20% off + free shipping","Your last chance to score 20% off + free shipping") -> 20% off + free shipping | H33: 0
F34: control | G34: =IF(ABTest[[#This Row],[group]]="control","20% off + free shipping","Your last chance to score 20% off + free shipping") -> 20% off + free shipping | H34: 0
F35: test | G35: =IF(ABTest[[#This Row],[group]]="control","20% off + free shipping","Your last chance to score 20% off + free shipping") -> Your last chance to score 20% off + free shipping | H35: 0
F36: test | G36: =IF(ABTest[[#This Row],[group]]="control","20% off + free shipping","Your last chance to score 20% off + free shipping") -> Your last chance to score 20% off + free shipping | H36: 0
F37: test | G37: =IF(ABTest[[#This Row],[group]]="control","20% off + free shipping","Your last chance to score 20% off + free shipping") -> Your last chance to score 20% off + free shipping | H37: 0
F38: test | G38: =IF(ABTest[[#This Row],[group]]="control","20% off + free shipping","Your last chance to score 20% off + free shipping") -> Your last chance to score 20% off + free shipping | H38: 0
A39: 1. Selection bias. If users aren't randomly assigned, one group may naturally have more active or engaged customers, so any difference in open rate reflects who received the email rather than the subject line itself. Mitigation: assign each unique customer ID to control or treatment using a random hash, and verify post-assignment that the two groups have similar past engagement, tenure, and segment mix before the send. 2. Time-based effects (seasonality). Open behavior shifts with day of week, time of day, paydays, and holidays, so if one variant is sent at a different moment than the other, that timing drives the result instead of the copy. Mitigation: send both variants simultaneously to their randomly assigned recipients, and avoid launching around major shopping events or holidays so external timing factors hit both groups equally. | F39: control | G39: =IF(ABTest[[#This Row],[group]]="control","20% off + free shipping","Your last chance to score 20% off + free shipping") -> 20% off + free shipping | H39: 0
F40: test | G40: =IF(ABTest[[#This Row],[group]]="control","20% off + free shipping","Your last chance to score 20% off + free shipping") -> Your last chance to score 20% off + free shipping | H40: 1
...

Sheet PivotTable
A9: Your actual PivotTable should go below this line.
A10: Row Labels | B10: Count of opened | C10: Sum of opened
A11: control | B11: 4764 | C11: 836
A12: test | B12: 4673 | C12: 894
A13: Grand Total | B13: 9437 | C13: 1730

Sheet Solutions
A1: Question | B1: Low Bound | C1: High Bound | D1: free-response-solution
A2: 1 | B2: free response | D2: =IF(ISBLANK(INDEX('AB Test Analysis'!$A$17:$C$18,1,1)), "no solution", IF(ISERROR(INDEX('AB Test Analysis'!$A$17:$C$18,1,1)), "error in parsing the solution", INDEX('AB Test Analysis'!$A$17:$C$18,1,1))) -> The subject line has no effect on the email open rate. The open rate for the test group is equal to the open rate for the control group.
A3: 2 | B3: free response | D3: =IF(ISBLANK(INDEX('AB Test Analysis'!$A$20:$C$21,1,1)), "no solution", IF(ISERROR(INDEX('AB Test Analysis'!$A$20:$C$21,1,1)), "error in parsing the solution", INDEX('AB Test Analysis'!$A$20:$C$21,1,1))) -> The urgency-based subject line produces a higher open rate than the control subject line.
A4: 3 | B4: 0.11 | C4: 0.1112 | D4: =IF(ISBLANK(INDEX('AB Test Analysis'!$C$26:$C$27,1,1)), "no solution", IF(ISERROR(INDEX('AB Test Analysis'!$C$26:$C$27,1,1)), "error in parsing the solution", INDEX('AB Test Analysis'!$C$26:$C$27,1,1))) -> 0.1111
A5: 4 | B5: 9300 | C5: 9400 | D5: =IF(ISBLANK(INDEX('AB Test Analysis'!$C$28:$C$29,1,1)), "no solution", IF(ISERROR(INDEX('AB Test Analysis'!$C$28:$C$29,1,1)), "error in parsing the solution", INDEX('AB Test Analysis'!$C$28:$C$29,1,1))) -> 9400
A6: 5 | B6: free response | D6: =IF(ISBLANK(INDEX('AB Test Analysis'!$A$39:$C$45,1,1)), "no solution", IF(ISERROR(INDEX('AB Test Analysis'!$A$39:$C$45,1,1)), "error in parsing the solution", INDEX('AB Test Analysis'!$A$39:$C$45,1,1))) -> 1. Selection bias. If users aren't randomly assigned, one group may naturally have more active or engaged customers, so any difference in open rate reflects who received the email rather than the subject line itself. Mitigation: assign each unique customer ID to control or treatment using a random hash, and verify post-assignment that the two groups have similar past engagement, tenure, and segment mix before the send. 2. Time-based effects (seasonality). Open behavior shifts with day of week, time of day, paydays, and holidays, so if one variant is sent at a different moment than the other, that timing drives the result instead of the copy. Mitigation: send both variants simultaneously to their randomly assigned recipients, and avoid launching around major shopping events or holidays so external timing factors hit both groups equally.
A7: 7 | B7: 91 | D7: =IF(ISBLANK(INDEX('AB Test Analysis'!$C$53:$C$54,1,1)), "no solution", IF(ISERROR(INDEX('AB Test Analysis'!$C$53:$C$54,1,1)), "error in parsing the solution", INDEX('AB Test Analysis'!$C$53:$C$54,1,1))) -> 91
A8: 8 | B8: 58 | D8: =IF(ISBLANK(INDEX('AB Test Analysis'!$C$55:$C$56,1,1)), "no solution", IF(ISERROR(INDEX('AB Test Analysis'!$C$55:$C$56,1,1)), "error in parsing the solution", INDEX('AB Test Analysis'!$C$55:$C$56,1,1))) -> 58
A9: 9 | B9: free response | D9: =IF(ISBLANK(INDEX('AB Test Analysis'!$A$61:$C$65,1,1)), "no solution", IF(ISERROR(INDEX('AB Test Analysis'!$A$61:$C$65,1,1)), "error in parsing the solution", INDEX('AB Test Analysis'!$A$61:$C$65,1,1))) -> The test group performed 19% better so it converted 10% better than the control group whicher performed 18% . I am 98% certain that the changes in the test group will improve conversion rate. The result is statistically significant with 98% confidence.
A10: 10 | B10: free response | D10: =IF(ISBLANK(INDEX('AB Test Analysis'!$A$69:$C$71,1,1)), "no solution", IF(ISERROR(INDEX('AB Test Analysis'!$A$69:$C$71,1,1)), "error in parsing the solution", INDEX('AB Test Analysis'!$A$69:$C$71,1,1))) -> Since we concluded the test group is better, the error we can make is a Type I error (false positive) , we rejecting the null hypothesis when it's actually true. In other words, we'd be claiming the new subject line improves open rates when in reality there's no real difference.
A11: 11 | B11: free response | D11: =IF(ISBLANK(INDEX('AB Test Analysis'!$A$77:$C$81,1,1)), "no solution", IF(ISERROR(INDEX('AB Test Analysis'!$A$77:$C$81,1,1)), "error in parsing the solution", INDEX('AB Test Analysis'!$A$77:$C$81,1,1))) -> Yes, H&M should continue using the new subject line ("Your last chance to score 20% off + free shipping"). The test group achieved a 19% open rate vs. 18% for the control and the result is statistically significant at 98% confidence. This means the improvement is very unlikely to be due to random chance, so the urgency-driven subject line genuinely helps achieve the goal of increasing email open rates. There could be a chance of a Type I error, so H&M could continue monitoring performance over time to confirm the lift holds.
A12: 12 | B12: free response | D12: =IF(ISBLANK(INDEX('AB Test Analysis'!$A$89:$C$95,1,1)), "no solution", IF(ISERROR(INDEX('AB Test Analysis'!$A$89:$C$95,1,1)), "error in parsing the solution", INDEX('AB Test Analysis'!$A$89:$C$95,1,1))) -> To balance these factors, H&M shouldn't rely on open rate alone since it's only a top-of-funnel metric. I think what matters is whether customer opens rate lead to actual revenue. The new subject line could attract curiosity-openers who don't convert, which could hurt long-term performance through unsubscribes or brand fatigue. I think that the additional factors that would significantly help improving the data includes click-through rate, conversion rate, revenue per email sent, average order value, item category purchased to see if customers are buying high-margin items or just discounted ones, unsubscribe rate, and customer lifetime value. H&M should only continue with the new subject line if the open-rate lift translates into higher revenue per email and doesn't increase unsubscribes.
